#每日一题/JavaScript 

当我们在 JavaScript 中编写代码时，我们使用 `try/catch` 语法来捕获和处理同步代码块中的异常。`try` 块用于包裹可能抛出异常的代码，而 `catch` 块则用于捕获和处理发生在 `try` 块中的异常。如果 `try` 块中的代码抛出了异常，那么异常会被传递到 `catch` 块中，并且我们可以在 `catch` 块中对其进行处理。

然而，`try/catch` 结构只能捕获同步代码中的异常，而不能捕获异步代码中的异常。这是因为异步代码在运行时会被放置在事件队列中，并在当前执行上下文执行完毕后才会被执行。而 `try/catch` 结构只能捕获当前执行上下文中的异常，无法捕获事件队列中的异常。

Promise 是一种处理异步操作的方式，它通过返回一个代表异步操作结果的 Promise 对象来处理异步操作。在 Promise 中，我们可以通过 `.then()` 方法和 `.catch()` 方法来处理异步操作的结果或错误。当 Promise 中的异步操作完成后，它会调用相应的回调函数。如果异步操作发生错误，它会调用 `.catch()` 回调函数并将错误对象作为参数传递给它。

因此，当我们使用 Promise 来处理异步操作时，错误是在异步操作完成后才会被处理的，而不是在当前执行上下文中立即抛出异常。这就导致 `try/catch` 结构无法捕获到 Promise 的错误。

为了捕获 Promise 中的错误，我们可以使用 `.catch()` 方法来处理 Promise 中的错误。通过将 `.catch()` 方法链式调用到 Promise 对象的末尾，我们可以在异步操作发生错误时捕获并处理它。

以下是一个使用 `try/catch` 无法捕获 Promise 错误的示例：

```javascript
try {
  setTimeout(() => {
    throw new Error('Async error');
  }, 1000);
} catch (error) {
  console.log('Caught an error:', error.message);
}
```

在上面的代码中，`setTimeout()` 是一个异步操作，`throw new Error('Async error')` 会在 1 秒后执行。但是 `try/catch` 结构无法捕获到这个错误，因为错误发生在异步操作完成后。

相反，我们可以使用 Promise 的 `.catch()` 方法来捕获 Promise 中的错误：

```javascript
new Promise((resolve, reject) => {
  setTimeout(() => {
    reject(new Error('Async error'));
  }, 1000);
})
  .then(result => {
    console.log('Promise resolved:', result);
  })
  .catch(error => {
    console.log('Promise rejected:', error.message);
  });
```

在上面的代码中，我们创建了一个 Promise 对象，并在异步操作完成后使用 `.catch()` 方法捕获错误。如果异步操作发生错误，它会将错误对象传递给 `.catch()` 回调函数，并在控制台中打印错误消息。

总结来说，`try/catch` 结构无法捕获 Promise 中的错误是因为 Promise 的执行是异步的，并不在当前执行上下文中进行。为了捕获 Promise 中的错误，我们需要使用 Promise 的 `.catch()` 方法来处理错误。